1328:0Traceback (most recent call last):
  File "/home/pidge/workspace/yocto-autobuilder/lib/python2.7/site-packages/Twisted-12.2.0-py2.7-linux-x86_64.egg/twisted/internet/defer.py", line 551, in _runCallbacks
    current.result = callback(current.result, *args, **kw)
  File "/home/pidge/workspace/yocto-autobuilder/lib/python2.7/site-packages/Twisted-12.2.0-py2.7-linux-x86_64.egg/twisted/internet/defer.py", line 1187, in unwindGenerator
    return _inlineCallbacks(None, gen, Deferred())
  File "/home/pidge/workspace/yocto-autobuilder/lib/python2.7/site-packages/Twisted-12.2.0-py2.7-linux-x86_64.egg/twisted/internet/defer.py", line 1045, in _inlineCallbacks
    result = g.send(result)
  File "/home/pidge/workspace/yocto-autobuilder/lib/python2.7/site-packages/buildbot-0.8.7p1-py2.7.egg/buildbot/process/buildstep.py", line 600, in _startStep_3
    result = yield defer.maybeDeferred(self.start)
--- <exception caught here> ---
  File "/home/pidge/workspace/yocto-autobuilder/lib/python2.7/site-packages/Twisted-12.2.0-py2.7-linux-x86_64.egg/twisted/internet/defer.py", line 134, in maybeDeferred
    result = f(*args, **kw)
  File "/home/pidge/workspace/yocto-autobuilder/lib/autobuilder/buildsteps/SetDest.py", line 60, in start
    return self.finished(SUCCESS)
exceptions.NameError: global name 'SUCCESS' is not defined
,